<?xml version="1.0" ?>
<robot name="quadruped_robot">
  <material name="white">
    <color rgba="1.0 1.0 1.0 1.000"/>
  </material>

  <material name="black">
    <color rgba="0.0 0.0 0.0 1.000"/>
  </material>

  <link name="world">
  </link>

  <joint name="base_joint" type="fixed">
    <origin rpy="0 0 0" xyz="0 0 0.5"/>
    <parent link="world"/>
    <child link="base_link"/>
  </joint>

  <link name="base_link">
    <inertial>
      <origin xyz="-1.403432864127373e-05 0.04089216246839065 0.00038276930859894374" rpy="0 0 0"/>
      <mass value="0.8505876351103128"/>
      <inertia ixx="0.000349" iyy="0.000569" izz="0.000337" ixy="-0.0" iyz="-1e-06" ixz="0.0"/>
    </inertial>
    <visual>
      <origin xyz="0 0 0" rpy="0 0 0"/>
      <geometry>
        <mesh filename="package://quadruped_robot_description/meshes/base_link.stl" scale="0.001 0.001 0.001"/>
      </geometry>
      <material name="black"/>
    </visual>
    <collision>
      <origin xyz="0 0 0" rpy="0 0 0"/>
      <geometry>
        <mesh filename="package://quadruped_robot_description/meshes/base_link.stl" scale="0.001 0.001 0.001"/>
      </geometry>
    </collision>
  </link>

  <link name="leg_3">
    <inertial>
      <origin xyz="-2.5004270480943896e-05 -0.008625177783152922 -0.0013116403224834225" rpy="0 0 0"/>
      <mass value="0.657885902828282"/>
      <inertia ixx="0.407634" iyy="0.769441" izz="0.410714" ixy="1.4e-05" iyz="-3e-06" ixz="0.0"/>
    </inertial>
    <visual>
      <origin xyz="0.0 -0.025 -0.0" rpy="0 0 0"/>
      <geometry>
        <mesh filename="package://quadruped_robot_description/meshes/leg_3.stl" scale="0.001 0.001 0.001"/>
      </geometry>
      <material name="white"/>
    </visual>
    <collision>
      <origin xyz="0.0 -0.025 -0.0" rpy="0 0 0"/>
      <geometry>
        <mesh filename="package://quadruped_robot_description/meshes/leg_3.stl" scale="0.001 0.001 0.001"/>
      </geometry>
    </collision>
  </link>

  <link name="gear_2">
    <inertial>
      <origin xyz="-1.4034328315678919e-05 -0.012107838485283868 0.00038276913820788224" rpy="0 0 0"/>
      <mass value="0.8505876351103128"/>
      <inertia ixx="0.000349" iyy="0.000569" izz="0.000337" ixy="-0.0" iyz="-1e-06" ixz="0.0"/>
    </inertial>
    <visual>
      <origin xyz="-0.0 -0.001 0.0" rpy="0 0 0"/>
      <geometry>
        <mesh filename="package://quadruped_robot_description/meshes/gear_2.stl" scale="0.001 0.001 0.001"/>
      </geometry>
      <material name="black"/>
    </visual>
    <collision>
      <origin xyz="-0.0 -0.001 0.0" rpy="0 0 0"/>
      <geometry>
        <mesh filename="package://quadruped_robot_description/meshes/gear_2.stl" scale="0.001 0.001 0.001"/>
      </geometry>
    </collision>
  </link>

  <link name="leg_2">
    <inertial>
      <origin xyz="0.10575373481330458 -0.006986344256198283 -0.03803796859205587" rpy="0 0 0"/>
      <mass value="2.0086761793539414"/>
      <inertia ixx="1.422506" iyy="6.564512" izz="5.194908" ixy="-0.081587" iyz="-0.001885" ixz="-0.018399"/>
    </inertial>
    <visual>
      <origin xyz="-0.0 0.024 0.0" rpy="0 0 0"/>
      <geometry>
        <mesh filename="package://quadruped_robot_description/meshes/leg_2.stl" scale="0.001 0.001 0.001"/>
      </geometry>
      <material name="white"/>
    </visual>
    <collision>
      <origin xyz="-0.0 0.024 0.0" rpy="0 0 0"/>
      <geometry>
        <mesh filename="package://quadruped_robot_description/meshes/leg_2.stl" scale="0.001 0.001 0.001"/>
      </geometry>
    </collision>
  </link>

  <link name="leg_1">
    <inertial>
      <origin xyz="-0.05550813708591157 0.0073015454849653105 -0.05052022573575653" rpy="0 0 0"/>
      <mass value="0.8145141492777319"/>
      <inertia ixx="0.00304" iyy="0.007185" izz="0.004192" ixy="0.0" iyz="0.0" ixz="-0.003392"/>
    </inertial>
    <visual>
      <origin xyz="-0.190612 0.044 0.11005" rpy="0 0 0"/>
      <geometry>
        <mesh filename="package://quadruped_robot_description/meshes/leg_1.stl" scale="0.001 0.001 0.001"/>
      </geometry>
      <material name="white"/>
    </visual>
    <collision>
      <origin xyz="-0.190612 0.044 0.11005" rpy="0 0 0"/>
      <geometry>
        <mesh filename="package://quadruped_robot_description/meshes/leg_1.stl" scale="0.001 0.001 0.001"/>
      </geometry>
    </collision>
  </link>

  <joint name="revolute1" type="revolute">
    <origin xyz="0.0 0.025 0.0" rpy="0 0 0"/>
    <parent link="base_link"/>
    <child link="leg_3"/>
    <axis xyz="0.0 -1.0 0.0"/>
    <limit effort="50" lower="-3.141592" upper="3.141592" velocity="20.0" />
    <dynamics damping="0.0" friction="10.0"/>
  </joint>

  <joint name="fixed1" type="fixed">
    <origin xyz="0.0 -0.024 -0.0" rpy="0 0 0"/>
    <parent link="leg_3"/>
    <child link="gear_2"/>
  </joint>

  <joint name="fixed2" type="fixed">
    <origin xyz="0.0 -0.025 0.0" rpy="0 0 0"/>
    <parent link="gear_2"/>
    <child link="leg_2"/>
  </joint>

  <joint name="revolute2" type="revolute">
    <origin xyz="0.190612 -0.02 -0.11005" rpy="0 0 0"/>
    <parent link="leg_2"/>
    <child link="leg_1"/>
    <axis xyz="0.0 -1.0 -0.0"/>
    <limit effort="50" lower="-3.141592" upper="3.141592" velocity="20.0" />
    <dynamics damping="0.0" friction="10.0"/>
  </joint>

  <gazebo reference="base_link">
    <material>Gazebo/Black</material>
    <selfCollide>true</selfCollide>
  </gazebo>
  <gazebo reference="leg_3">
    <material>Gazebo/White</material>
    <selfCollide>true</selfCollide>
  </gazebo>
  <gazebo reference="gear_2">
    <material>Gazebo/Black</material>
    <selfCollide>true</selfCollide>
  </gazebo>
  <gazebo reference="leg_2">
    <material>Gazebo/White</material>
    <selfCollide>true</selfCollide>
  </gazebo>
  <gazebo reference="leg_1">
    <material>Gazebo/White</material>
    <selfCollide>true</selfCollide>
  </gazebo>
</robot>
